Workbook

Sheet About
A1: BVS BAU Vehicle Subsidy (rebuilt 2026-06) | B1: Wyoming | C1: 46266 | F1: State | G1: State
B2: =LOOKUP(B1,F2:G51,G2:G51) -> WY | F2: Alabama | G2: AL
A3: Sources: | B3: Federal: IRA clean-vehicle credits (30D new / 25E used / 45W commercial), TERMINATED by OBBBA (P.L.119-21) for vehicles acquired after 2025-09-30. Federal values = ICCT/Energy Innovation weighted-credit analysis. | F3: Alaska | G3: AK
B4: IRS OBBBA FAQ: https://www.irs.gov/newsroom/one-big-beautiful-bill-provisions | F4: Arizona | G4: AZ
B5: ICCT / Energy Innovation IRA EV analysis: https://energyinnovation.org/publication/analyzing-the-impact-of-the-inflation-reduction-act-on-electric-vehicle-uptake-in-the-united-states/ | F5: Arkansas | G5: AR
F6: California | G6: CA
B7: State Laws | F7: Colorado | G7: CO
B8: Alternative Fuels Data Center | F8: Connecticut | G8: CT
B9: State Laws and Incentives | F9: Delaware | G9: DE
B10: https://afdc.energy.gov/laws/state | F10: Florida | G10: FL
B11: 2026 | F11: Georgia | G11: GA
F12: Hawaii | G12: HI
F13: Idaho | G13: ID
F14: Illinois | G14: IL
A15: NOTES | F15: Indiana | G15: IN
A16: State EV purchase rebates/credits: see the State EV Rebates tab (per-state amounts, status, and primary-source URL). Compiled from state agency pages + U.S. DOE AFDC (afdc.energy.gov/laws/state); current as of mid-2026. | F16: Iowa | G16: IA
A17: CPI-U deflators to 2012$ (CPI_2012=229.594): BLS, actuals through 2024; 2025=322.0, 2026=335.1 (May 2026), ~2.8%/yr after. https://www.bls.gov/cpi/ | F17: Kansas | G17: KS
F18: Kentucky | G18: KY
A19: All values in 2012 USD. BAU assumptions (flag for staff review): state programs held at current amount through 2030 then $0; suspended/exhausted-but-ongoing programs (OR, VT, MD) valued at standard amount; income-only programs (ME, WA) = $0. | F19: Louisiana | G19: LA
F20: Maine | G20: ME
F21: Maryland | G21: MD
F22: Massachusetts | G22: MA
F23: Michigan | G23: MI
F24: Minnesota | G24: MN
F25: Mississippi | G25: MS
F26: Missouri | G26: MO
F27: Montana | G27: MT
F28: Nebraska | G28: NE
F29: Nevada | G29: NV
F30: New Hampshire | G30: NH
F31: New Jersey | G31: NJ
... F51: Wyoming | G51: WY

Sheet Passenger Vehicle Calculations
A1: Federal EV Subsidy Amount (2012$)
A2: These values come from our internal analysis of weighted 30D and 45W purchase and leasing credits. (ICCT spreadsheet)
A3: Updated 2/11/25
B4: 2021 | C4: 2022 | D4: 2023 | E4: 2024 | F4: 2025 | G4: 2026 | H4: 2027 | I4: 2028 | J4: 2029 | K4: 2030 | L4: 2031 | M4: 2032 | N4: 2033 | O4: 2034 | P4: 2035 | Q4: 2036 | R4: 2037 | S4: 2038 | T4: 2039 | U4: 2040 | V4: 2041 | W4: 2042 | X4: 2043 | Y4: 2044 | Z4: 2045 | AA4: 2046 | AB4: 2047 | AC4: 2048 | AD4: 2049 | AE4: 2050
A5: battery electric vehicles | B5: 1646.4981 | C5: 1368.5858 | D5: 4795.9637 | E5: 3555.4877 | F5: 3365.6877 | G5: 3118.2247 | H5: 2391.1776 | I5: 2424.5099 | J5: 2459.8873 | K5: 2497.1121 | L5: 2525.3972 | M5: 2552.5013 | N5: 0 | O5: 0 | P5: 0 | Q5: 0 | R5: 0 | S5: 0 | T5: 0 | U5: 0 | V5: 0 | W5: 0 | X5: 0 | Y5: 0 | Z5: 0 | AA5: 0 | AB5: 0 | AC5: 0 | AD5: 0 | AE5: 0
A6: plugin hybrid vehicles | B6: 6652.7185 | C6: 3617.0507 | D6: 3481.1983 | E6: 2846.5223 | F6: 2396.2167 | G6: 2262.2796 | H6: 2133.3804 | I6: 2079.448 | J6: 2027.139 | K6: 1976.3953 | L6: 1926.1485 | M6: 1877.1377 | N6: 0 | O6: 0 | P6: 0 | Q6: 0 | R6: 0 | S6: 0 | T6: 0 | U6: 0 | V6: 0 | W6: 0 | X6: 0 | Y6: 0 | Z6: 0 | AA6: 0 | AB6: 0 | AC6: 0 | AD6: 0 | AE6: 0
A7: OBBBA federal-credit availability factor (1=full, 0.75=2025 partial, 0 from 2026) | B7: 1 | C7: 1 | D7: 1 | E7: 1 | F7: 0.75 | G7: 0 | H7: 0 | I7: 0 | J7: 0 | K7: 0 | L7: 0 | M7: 0 | N7: 0 | O7: 0 | P7: 0 | Q7: 0 | R7: 0 | S7: 0 | T7: 0 | U7: 0 | V7: 0 | W7: 0 | X7: 0 | Y7: 0 | Z7: 0 | AA7: 0 | AB7: 0 | AC7: 0 | AD7: 0 | AE7: 0
C13: https://www.energysage.com/electric-vehicles/costs-and-benefits-evs/ev-tax-credits/
C14: https://www.tesla.com/support/incentives
R18: https://afdc.energy.gov/laws/11609
A61: State subsidy (2012$) = active state rebate (SUMIFS by About!B2 into State EV Rebates tab) x CPI deflator
C62: 2021 | D62: 2022 | E62: 2023 | F62: 2024 | G62: 2025 | H62: 2026 | I62: 2027 | J62: 2028 | K62: 2029 | L62: 2030 | M62: 2031 | N62: 2032 | O62: 2033 | P62: 2034 | Q62: 2035 | R62: 2036 | S62: 2037 | T62: 2038 | U62: 2039 | V62: 2040 | W62: 2041 | X62: 2042 | Y62: 2043 | Z62: 2044 | AA62: 2045 | AB62: 2046 | AC62: 2047 | AD62: 2048 | AE62: 2049 | AF62: 2050
A63: battery electric vehicles | C63: =SUMIFS('State EV Rebates'!$C$5:$C$24,'State EV Rebates'!$A$5:$A$24,About!$B$2)*$L$79 -> 0 | D63: =SUMIFS('State EV Rebates'!$D$5:$D$24,'State EV Rebates'!$A$5:$A$24,About!$B$2)*$M$79 -> 0 | E63: =SUMIFS('State EV Rebates'!$E$5:$E$24,'State EV Rebates'!$A$5:$A$24,About!$B$2)*$N$79 -> 0 | F63: =SUMIFS('State EV Rebates'!$F$5:$F$24,'State EV Rebates'!$A$5:$A$24,About!$B$2)*$O$79 -> 0 | G63: =SUMIFS('State EV Rebates'!$G$5:$G$24,'State EV Rebates'!$A$5:$A$24,About!$B$2)*$P$79 -> 0 | H63: =SUMIFS('State EV Rebates'!$H$5:$H$24,'State EV Rebates'!$A$5:$A$24,About!$B$2)*$Q$79 -> 0 | I63: =SUMIFS('State EV Rebates'!$I$5:$I$24,'State EV Rebates'!$A$5:$A$24,About!$B$2)*$R$79 -> 0 | J63: =SUMIFS('State EV Rebates'!$J$5:$J$24,'State EV Rebates'!$A$5:$A$24,About!$B$2)*$S$79 -> 0 | K63: =SUMIFS('State EV Rebates'!$K$5:$K$24,'State EV Rebates'!$A$5:$A$24,About!$B$2)*$T$79 -> 0 | L63: =SUMIFS('State EV Rebates'!$L$5:$L$24,'State EV Rebates'!$A$5:$A$24,About!$B$2)*$U$79 -> 0 | M63: =SUMIFS('State EV Rebates'!$M$5:$M$24,'State EV Rebates'!$A$5:$A$24,About!$B$2)*$V$79 -> 0 | N63: =SUMIFS('State EV Rebates'!$N$5:$N$24,'State EV Rebates'!$A$5:$A$24,About!$B$2)*$W$79 -> 0 | O63: =SUMIFS('State EV Rebates'!$O$5:$O$24,'State EV Rebates'!$A$5:$A$24,About!$B$2)*$X$79 -> 0 | P63: =SUMIFS('State EV Rebates'!$P$5:$P$24,'State EV Rebates'!$A$5:$A$24,About!$B$2)*$Y$79 -> 0 | Q63: =SUMIFS('State EV Rebates'!$Q$5:$Q$24,'State EV Rebates'!$A$5:$A$24,About!$B$2)*$Z$79 -> 0 | R63: =SUMIFS('State EV Rebates'!$R$5:$R$24,'State EV Rebates'!$A$5:$A$24,About!$B$2)*$AA$79 -> 0 | S63: =SUMIFS('State EV Rebates'!$S$5:$S$24,'State EV Rebates'!$A$5:$A$24,About!$B$2)*$AB$79 -> 0 | T63: =SUMIFS('State EV Rebates'!$T$5:$T$24,'State EV Rebates'!$A$5:$A$24,About!$B$2)*$AC$79 -> 0 | U63: =SUMIFS('State EV Rebates'!$U$5:$U$24,'State EV Rebates'!$A$5:$A$24,About!$B$2)*$AD$79 -> 0 | V63: =SUMIFS('State EV Rebates'!$V$5:$V$24,'State EV Rebates'!$A$5:$A$24,About!$B$2)*$AE$79 -> 0 | W63: =SUMIFS('State EV Rebates'!$W$5:$W$24,'State EV Rebates'!$A$5:$A$24,About!$B$2)*$AF$79 -> 0 | X63: =SUMIFS('State EV Rebates'!$X$5:$X$24,'State EV Rebates'!$A$5:$A$24,About!$B$2)*$AG$79 -> 0 | Y63: =SUMIFS('State EV Rebates'!$Y$5:$Y$24,'State EV Rebates'!$A$5:$A$24,About!$B$2)*$AH$79 -> 0 | Z63: =SUMIFS('State EV Rebates'!$Z$5:$Z$24,'State EV Rebates'!$A$5:$A$24,About!$B$2)*$AI$79 -> 0 | AA63: =SUMIFS('State EV Rebates'!$AA$5:$AA$24,'State EV Rebates'!$A$5:$A$24,About!$B$2)*$AJ$79 -> 0 | AB63: =SUMIFS('State EV Rebates'!$AB$5:$AB$24,'State EV Rebates'!$A$5:$A$24,About!$B$2)*$AK$79 -> 0 | AC63: =SUMIFS('State EV Rebates'!$AC$5:$AC$24,'State EV Rebates'!$A$5:$A$24,About!$B$2)*$AL$79 -> 0 | AD63: =SUMIFS('State EV Rebates'!$AD$5:$AD$24,'State EV Rebates'!$A$5:$A$24,About!$B$2)*$AM$79 -> 0 | AE63: =SUMIFS('State EV Rebates'!$AE$5:$AE$24,'State EV Rebates'!$A$5:$A$24,About!$B$2)*$AN$79 -> 0 | AF63: =SUMIFS('State EV Rebates'!$AF$5:$AF$24,'State EV Rebates'!$A$5:$A$24,About!$B$2)*$AO$79 -> 0
A64: plugin hybrid vehicles | C64: =SUMIFS('State EV Rebates'!$C$28:$C$47,'State EV Rebates'!$A$28:$A$47,About!$B$2)*$L$79 -> 0 | D64: =SUMIFS('State EV Rebates'!$D$28:$D$47,'State EV Rebates'!$A$28:$A$47,About!$B$2)*$M$79 -> 0 | E64: =SUMIFS('State EV Rebates'!$E$28:$E$47,'State EV Rebates'!$A$28:$A$47,About!$B$2)*$N$79 -> 0 | F64: =SUMIFS('State EV Rebates'!$F$28:$F$47,'State EV Rebates'!$A$28:$A$47,About!$B$2)*$O$79 -> 0 | G64: =SUMIFS('State EV Rebates'!$G$28:$G$47,'State EV Rebates'!$A$28:$A$47,About!$B$2)*$P$79 -> 0 | H64: =SUMIFS('State EV Rebates'!$H$28:$H$47,'State EV Rebates'!$A$28:$A$47,About!$B$2)*$Q$79 -> 0 | I64: =SUMIFS('State EV Rebates'!$I$28:$I$47,'State EV Rebates'!$A$28:$A$47,About!$B$2)*$R$79 -> 0 | J64: =SUMIFS('State EV Rebates'!$J$28:$J$47,'State EV Rebates'!$A$28:$A$47,About!$B$2)*$S$79 -> 0 | K64: =SUMIFS('State EV Rebates'!$K$28:$K$47,'State EV Rebates'!$A$28:$A$47,About!$B$2)*$T$79 -> 0 | L64: =SUMIFS('State EV Rebates'!$L$28:$L$47,'State EV Rebates'!$A$28:$A$47,About!$B$2)*$U$79 -> 0 | M64: =SUMIFS('State EV Rebates'!$M$28:$M$47,'State EV Rebates'!$A$28:$A$47,About!$B$2)*$V$79 -> 0 | N64: =SUMIFS('State EV Rebates'!$N$28:$N$47,'State EV Rebates'!$A$28:$A$47,About!$B$2)*$W$79 -> 0 | O64: =SUMIFS('State EV Rebates'!$O$28:$O$47,'State EV Rebates'!$A$28:$A$47,About!$B$2)*$X$79 -> 0 | P64: =SUMIFS('State EV Rebates'!$P$28:$P$47,'State EV Rebates'!$A$28:$A$47,About!$B$2)*$Y$79 -> 0 | Q64: =SUMIFS('State EV Rebates'!$Q$28:$Q$47,'State EV Rebates'!$A$28:$A$47,About!$B$2)*$Z$79 -> 0 | R64: =SUMIFS('State EV Rebates'!$R$28:$R$47,'State EV Rebates'!$A$28:$A$47,About!$B$2)*$AA$79 -> 0 | S64: =SUMIFS('State EV Rebates'!$S$28:$S$47,'State EV Rebates'!$A$28:$A$47,About!$B$2)*$AB$79 -> 0 | T64: =SUMIFS('State EV Rebates'!$T$28:$T$47,'State EV Rebates'!$A$28:$A$47,About!$B$2)*$AC$79 -> 0 | U64: =SUMIFS('State EV Rebates'!$U$28:$U$47,'State EV Rebates'!$A$28:$A$47,About!$B$2)*$AD$79 -> 0 | V64: =SUMIFS('State EV Rebates'!$V$28:$V$47,'State EV Rebates'!$A$28:$A$47,About!$B$2)*$AE$79 -> 0 | W64: =SUMIFS('State EV Rebates'!$W$28:$W$47,'State EV Rebates'!$A$28:$A$47,About!$B$2)*$AF$79 -> 0 | X64: =SUMIFS('State EV Rebates'!$X$28:$X$47,'State EV Rebates'!$A$28:$A$47,About!$B$2)*$AG$79 -> 0 | Y64: =SUMIFS('State EV Rebates'!$Y$28:$Y$47,'State EV Rebates'!$A$28:$A$47,About!$B$2)*$AH$79 -> 0 | Z64: =SUMIFS('State EV Rebates'!$Z$28:$Z$47,'State EV Rebates'!$A$28:$A$47,About!$B$2)*$AI$79 -> 0 | AA64: =SUMIFS('State EV Rebates'!$AA$28:$AA$47,'State EV Rebates'!$A$28:$A$47,About!$B$2)*$AJ$79 -> 0 | AB64: =SUMIFS('State EV Rebates'!$AB$28:$AB$47,'State EV Rebates'!$A$28:$A$47,About!$B$2)*$AK$79 -> 0 | AC64: =SUMIFS('State EV Rebates'!$AC$28:$AC$47,'State EV Rebates'!$A$28:$A$47,About!$B$2)*$AL$79 -> 0 | AD64: =SUMIFS('State EV Rebates'!$AD$28:$AD$47,'State EV Rebates'!$A$28:$A$47,About!$B$2)*$AM$79 -> 0 | AE64: =SUMIFS('State EV Rebates'!$AE$28:$AE$47,'State EV Rebates'!$A$28:$A$47,About!$B$2)*$AN$79 -> 0 | AF64: =SUMIFS('State EV Rebates'!$AF$28:$AF$47,'State EV Rebates'!$A$28:$A$47,About!$B$2)*$AO$79 -> 0
A66: Total Tax Credit (2012$)
C67: 2021 | D67: 2022 | E67: 2023 | F67: 2024 | G67: 2025 | H67: 2026 | I67: 2027 | J67: 2028 | K67: 2029 | L67: 2030 | M67: 2031 | N67: 2032 | O67: 2033 | P67: 2034 | Q67: 2035 | R67: 2036 | S67: 2037 | T67: 2038 | U67: 2039 | V67: 2040 | W67: 2041 | X67: 2042 | Y67: 2043 | Z67: 2044 | AA67: 2045 | AB67: 2046 | AC67: 2047 | AD67: 2048 | AE67: 2049 | AF67: 2050
A68: battery electric vehicles | C68: =B5*B7+C63 -> 1646.4981 | D68: =C5*C7+D63 -> 1368.5858 | E68: =D5*D7+E63 -> 4795.9637 | F68: =E5*E7+F63 -> 3555.4877 | G68: =F5*F7+G63 -> 2524.2658 | H68: =G5*G7+H63 -> 0 | I68: =H5*H7+I63 -> 0 | J68: =I5*I7+J63 -> 0 | ... AF68: =AE5*AE7+AF63 -> 0
A69: plugin hybrid vehicles | C69: =B6*B7+C64 -> 6652.7185 | D69: =C6*C7+D64 -> 3617.0507 | E69: =D6*D7+E64 -> 3481.1983 | F69: =E6*E7+F64 -> 2846.5223 | G69: =F6*F7+G64 -> 1797.1625 | H69: =G6*G7+H64 -> 0 | I69: =H6*H7+I64 -> 0 | J69: =I6*I7+J64 -> 0 | ... AF69: =AE6*AE7+AF64 -> 0
D73: US average share of EVs leased vs purchased
D74: https://www.experian.com/blogs/ask-experian/electric-vehicle-trends/
D75: 2020 | E75: 2021 | F75: 2022 | G75: 2023 | H75: 2024 | I75: 2025 | J75: 2026
D76: 0.2467 | E76: 0.3092 | F76: 0.141 | G76: 0.2173 | H76: 0.4656 | I76: =H76 -> 0.4656 | J76: =I76 -> 0.4656
C78: 2012 | D78: 2013 | E78: 2014 | F78: 2015 | G78: 2016 | H78: 2017 | I78: 2018 | J78: 2019 | K78: 2020 | L78: 2021 | M78: 2022 | N78: 2023 | O78: 2024 | P78: 2025 | Q78: 2026 | R78: 2027 | S78: 2028 | T78: 2029 | U78: 2030 | V78: 2031 | W78: 2032 | X78: 2033 | Y78: 2034 | Z78: 2035 | AA78: 2036 | AB78: 2037 | AC78: 2038 | AD78: 2039 | AE78: 2040 | AF78: 2041 | AG78: 2042 | AH78: 2043 | AI78: 2044 | AJ78: 2045 | AK78: 2046 | AL78: 2047 | AM78: 2048 | AN78: 2049 | AO78: 2050
B79: Inflation adjuster | C79: 1 | D79: 0.985564 | E79: 0.969831 | F79: 0.968682 | G79: 0.956614 | H79: 0.93666 | I79: 0.914327 | J79: 0.898055 | K79: 0.887111 | L79: 0.847304 | M79: 0.784521 | N79: 0.753503 | O79: 0.731916 | P79: 0.713025 | Q79: 0.685151 | R79: 0.666489 | S79: 0.648334 | T79: 0.630675 | U79: 0.613497 | V79: 0.596787 | W79: 0.580532 | X79: 0.564719 | Y79: 0.549338 | Z79: 0.534374 | AA79: 0.51982 | AB79: 0.505661 | AC79: 0.491889 | AD79: 0.478491 | AE79: 0.465459 | AF79: 0.452781 | AG79: 0.440449 | AH79: 0.428452 | AI79: 0.416782 | AJ79: 0.40543 | AK79: 0.394388 | AL79: 0.383646 | AM79: 0.373196 | AN79: 0.363031 | AO79: 0.353143
A82: Inflation Historical Data and Assumptions | D82: Future inflation assumption: | G82: 0.03
A84: 2012............................................................................. . | B84: 228.85 | C84: 230.338 | D84: 229.594 | E84: 1.7 | F84: 2.1 | G84: 1
A85: 2013............................................................................. . | B85: 232.366 | C85: 233.548 | D85: 232.957 | E85: 1.5 | F85: 1.5 | G85: 0.985564
A86: 2014............................................................................. . | B86: 236.384 | C86: 237.088 | D86: 236.736 | E86: 0.8 | F86: 1.6 | G86: 0.969831
A87: 2015............................................................................. . | B87: 236.265 | C87: 237.769 | D87: 237.017 | E87: 0.7 | F87: 0.1 | G87: 0.968682
A88: 2016............................................................................. . | B88: 238.778 | C88: 241.237 | D88: 240.007 | E88: 2.1 | F88: 1.3 | G88: 0.956614
A89: 2017............................................................................. . | B89: 244.076 | C89: 246.163 | D89: 245.12 | E89: 2.1 | F89: 2.1 | G89: 0.93666
A90: 2018............................................................................. . | B90: 250.089 | C90: 252.125 | D90: 251.107 | E90: 1.9 | F90: 2.4 | G90: 0.914327
A91: 2019............................................................................. . | B91: 254.412 | C91: 256.903 | D91: 255.657 | E91: 2.3 | F91: 1.8 | G91: 0.898055
A92: 2020............................................................................. . | B92: 257.557 | C92: 260.065 | D92: 258.811 | E92: 1.4 | F92: 1.2 | G92: 0.887111
A93: 2021............................................................................. . | B93: 266.236 | C93: 275.703 | D93: 270.97 | E93: 7 | F93: 4.7 | G93: 0.847304
A94: 2022............................................................................. . | B94: 288.347 | C94: 296.963 | D94: 292.655 | E94: 6.5 | F94: 8 | G94: 0.784521
A95: 2023............................................................................. . | B95: 302.408 | C95: 306.996 | D95: 304.702 | G95: 0.753503
A96: 2024............................................................................. . | B96: 312.145 | C96: 315.233 | D96: 313.689 | G96: 0.731916
A97: 2025 | D97: =D96*(1+F97) -> 323.09967 | F97: =G$82 -> 0.03 | G97: 0.710598
A98: 2026 | D98: =D97*(1+F98) -> 332.79266 | F98: =G$82 -> 0.03 | G98: 0.689901
...

Sheet State EV Rebates
A1: State EV purchase rebates/credits - nominal $ per vehicle (raw policy data; current as of 2026-06)
A2: Scope: purchase rebate/credit on the vehicle only (not EVSE, not tax exemptions); broadly-available amount (income-only programs => 0). Inputs for staff review - verify vs Source column.
A4: BEV subsidy (nominal $) | B4: State | C4: 2021 | D4: 2022 | E4: 2023 | F4: 2024 | G4: 2025 | H4: 2026 | I4: 2027 | J4: 2028 | K4: 2029 | L4: 2030 | M4: 2031 | N4: 2032 | O4: 2033 | P4: 2034 | Q4: 2035 | R4: 2036 | S4: 2037 | T4: 2038 | U4: 2039 | V4: 2040 | W4: 2041 | X4: 2042 | Y4: 2043 | Z4: 2044 | AA4: 2045 | AB4: 2046 | AC4: 2047 | AD4: 2048 | AE4: 2049 | AF4: 2050 | AG4: Status | AH4: Income note | AI4: Source
A5: CO | B5: Colorado | C5: 2964 | D5: 2712 | E5: 3913 | F5: 5000 | G5: 3500 | H5: 750 | I5: 750 | J5: 750 | K5: 750 | L5: 750 | M5: 0 | N5: 0 | O5: 0 | P5: 0 | Q5: 0 | R5: 0 | S5: 0 | T5: 0 | U5: 0 | V5: 0 | W5: 0 | X5: 0 | Y5: 0 | Z5: 0 | AA5: 0 | AB5: 0 | AC5: 0 | AD5: 0 | AE5: 0 | AF5: 0 | AG5: Active; Innovative Motor Vehicle Credit cut $3,500->$750 on 1/1/2026 (MSRP<=$80k; +$2,500 if MSRP<$35k) | AH5: No | AI5: https://tax.colorado.gov/electric-vehicle-tax-credits
A6: CT | B6: Connecticut | C6: 233 | D6: 245 | E6: 842 | F6: 706 | G6: 471 | H6: 1000 | I6: 1000 | J6: 1000 | K6: 1000 | L6: 1000 | M6: 0 | N6: 0 | O6: 0 | P6: 0 | Q6: 0 | R6: 0 | S6: 0 | T6: 0 | U6: 0 | V6: 0 | W6: 0 | X6: 0 | Y6: 0 | Z6: 0 | AA6: 0 | AB6: 0 | AC6: 0 | AD6: 0 | AE6: 0 | AF6: 0 | AG6: Active; CHEAPR base ($1,000 BEV/$500 PHEV); Rebate+ higher for income-qualified | AH6: Base no | AI6: https://portal.ct.gov/DEEP/Air/Mobile-Sources/CHEAPR/CHEAPR---Home
A7: DE | B7: Delaware | C7: 2500 | D7: 2500 | E7: 2500 | F7: 2500 | G7: 2500 | H7: 2500 | I7: 2500 | J7: 2500 | K7: 2500 | L7: 2500 | M7: 0 | N7: 0 | O7: 0 | P7: 0 | Q7: 0 | R7: 0 | S7: 0 | T7: 0 | U7: 0 | V7: 0 | W7: 0 | X7: 0 | Y7: 0 | Z7: 0 | AA7: 0 | AB7: 0 | AC7: 0 | AD7: 0 | AE7: 0 | AF7: 0 | AG7: Active; Clean Vehicle Rebate ($2,500 BEV MSRP<$40k; $1,000 PHEV) | AH7: No | AI7: https://driveelectricdelaware.org/program-overview
A8: NY | B8: New York | C8: 910 | D8: 574 | E8: 553 | F8: 352 | G8: 352 | H8: 2000 | I8: 2000 | J8: 2000 | K8: 2000 | L8: 2000 | M8: 0 | N8: 0 | O8: 0 | P8: 0 | Q8: 0 | R8: 0 | S8: 0 | T8: 0 | U8: 0 | V8: 0 | W8: 0 | X8: 0 | Y8: 0 | Z8: 0 | AA8: 0 | AB8: 0 | AC8: 0 | AD8: 0 | AE8: 0 | AF8: 0 | AG8: Active; Drive Clean Rebate (tiered $500-$2,000; using $2,000 BEV top tier). Historical = realized average | AH8: No | AI8: https://www.nyserda.ny.gov/All-Programs/Drive-Clean-Rebate-For-Electric-Cars-Program
A9: TX | B9: Texas | C9: 0 | D9: 0 | E9: 0 | F9: 0 | G9: 0 | H9: 0 | I9: 0 | J9: 0 | K9: 0 | L9: 0 | M9: 0 | N9: 0 | O9: 0 | P9: 0 | Q9: 0 | R9: 0 | S9: 0 | T9: 0 | U9: 0 | V9: 0 | W9: 0 | X9: 0 | Y9: 0 | Z9: 0 | AA9: 0 | AB9: 0 | AC9: 0 | AD9: 0 | AE9: 0 | AF9: 0 | AG9: Ended for EVs (LDPLIP EV funding removed, announced Dec 2025) | AH9: n/a | AI9: https://www.tceq.texas.gov/airquality/terp/ldplip
A10: CA | B10: California | C10: 646 | D10: 338 | E10: 829 | F10: 0 | G10: 0 | H10: 0 | I10: 0 | J10: 0 | K10: 0 | L10: 0 | M10: 0 | N10: 0 | O10: 0 | P10: 0 | Q10: 0 | R10: 0 | S10: 0 | T10: 0 | U10: 0 | V10: 0 | W10: 0 | X10: 0 | Y10: 0 | Z10: 0 | AA10: 0 | AB10: 0 | AC10: 0 | AD10: 0 | AE10: 0 | AF10: 0 | AG10: CVRP ended 11/8/2023; successor programs income-limited (excluded under scope) | AH10: n/a | AI10: https://ww2.arb.ca.gov/news/californias-clean-vehicle-rebate-program-will-transition-helping-low-income-residents
A11: LA | B11: Louisiana | C11: 0 | D11: 0 | E11: 0 | F11: 0 | G11: 0 | H11: 0 | I11: 0 | J11: 0 | K11: 0 | L11: 0 | M11: 0 | N11: 0 | O11: 0 | P11: 0 | Q11: 0 | R11: 0 | S11: 0 | T11: 0 | U11: 0 | V11: 0 | W11: 0 | X11: 0 | Y11: 0 | Z11: 0 | AA11: 0 | AB11: 0 | AC11: 0 | AD11: 0 | AE11: 0 | AF11: 0 | AG11: No current state EV purchase incentive (AFV credit ended 2021) | AH11: n/a | AI11: https://afdc.energy.gov/laws/6603
A12: ME | B12: Maine | C12: 2000 | D12: 2000 | E12: 2000 | F12: 2000 | G12: 0 | H12: 0 | I12: 0 | J12: 0 | K12: 0 | L12: 0 | M12: 0 | N12: 0 | O12: 0 | P12: 0 | Q12: 0 | R12: 0 | S12: 0 | T12: 0 | U12: 0 | V12: 0 | W12: 0 | X12: 0 | Y12: 0 | Z12: 0 | AA12: 0 | AB12: 0 | AC12: 0 | AD12: 0 | AE12: 0 | AF12: 0 | AG12: Income-qualified only now ($6k-$8k low/moderate income); no all-income tier => $0 broadly available | AH12: Income-only | AI12: https://efficiencymaine.com/electric-vehicle-incentives-for-low-and-moderate-income/
A13: MN | B13: Minnesota | C13: 0 | D13: 0 | E13: 2500 | F13: 2500 | G13: 0 | H13: 0 | I13: 0 | J13: 0 | K13: 0 | L13: 0 | M13: 0 | N13: 0 | O13: 0 | P13: 0 | Q13: 0 | R13: 0 | S13: 0 | T13: 0 | U13: 0 | V13: 0 | W13: 0 | X13: 0 | Y13: 0 | Z13: 0 | AA13: 0 | AB13: 0 | AC13: 0 | AD13: 0 | AE13: 0 | AF13: 0 | AG13: Rebate funds exhausted/closed (2025); not accepting applications | AH13: n/a | AI13: https://mn.gov/commerce/energy/consumer/energy-programs/ev-rebates.jsp
A14: MD | B14: Maryland | C14: 2500 | D14: 2500 | E14: 3000 | F14: 3000 | G14: 3000 | H14: 3000 | I14: 3000 | J14: 3000 | K14: 3000 | L14: 3000 | M14: 0 | N14: 0 | O14: 0 | P14: 0 | Q14: 0 | R14: 0 | S14: 0 | T14: 0 | U14: 0 | V14: 0 | W14: 0 | X14: 0 | Y14: 0 | Z14: 0 | AA14: 0 | AB14: 0 | AC14: 0 | AD14: 0 | AE14: 0 | AF14: 0 | AG14: Excise-tax credit ~$3,000 (MSRP<=$50k); statutorily active thru 6/30/2027 but FY26 funds depleted (waitlist) - FLAG | AH14: No | AI14: https://mva.maryland.gov/vehicles/Pages/excise-tax-credit-plug-in-electric.aspx
A15: MA | B15: Massachusetts | C15: 2500 | D15: 2500 | E15: 3500 | F15: 3500 | G15: 3500 | H15: 3500 | I15: 3500 | J15: 3500 | K15: 3500 | L15: 3500 | M15: 0 | N15: 0 | O15: 0 | P15: 0 | Q15: 0 | R15: 0 | S15: 0 | T15: 0 | U15: 0 | V15: 0 | W15: 0 | X15: 0 | Y15: 0 | Z15: 0 | AA15: 0 | AB15: 0 | AC15: 0 | AD15: 0 | AE15: 0 | AF15: 0 | AG15: Active; MOR-EV $3,500 BEV (MSRP<=$55k). PHEVs phased out 2023 ($0) | AH15: Base no | AI15: https://mor-ev.org/faqs
... A47: VA | B47: Virginia | C47: 0 | D47: 0 | E47: 0 | F47: 0 | G47: 0 | H47: 0 | I47: 0 | J47: 0 | K47: 0 | L47: 0 | M47: 0 | N47: 0 | O47: 0 | P47: 0 | Q47: 0 | R47: 0 | S47: 0 | T47: 0 | U47: 0 | V47: 0 | W47: 0 | X47: 0 | Y47: 0 | Z47: 0 | AA47: 0 | AB47: 0 | AC47: 0 | AD47: 0 | AE47: 0 | AF47: 0 | AG47: EV rebate established in Code of Virginia but UNFUNDED (no payouts); sunset 1/1/2027 => $0 | AH47: n/a | AI47: https://law.lis.virginia.gov/vacodefull/title45.2/chapter17/article8/

Sheet Commercial Vehicles
A1: Methodology:
A2: For commercial vehicle credits, we find that the credit caps of $7,500 for vehicles under 14,000 pounds or $40,000 for vehicles over 14,000 pounds apply in all years. We apply the credit to all new sales of commercial trucks, using a weighted average credit value for our freight LDV category which covers both light and medium duty trucks. We also apply the credit to a fraction of buses, excluding buses purchased by the government. The credit runs from 2023-2032.
A3: OBBBA (P.L.119-21): Section 45W commercial credit terminated for vehicles acquired after 2025-09-30; applied via row 6 factor (2025 = 9/12, 0 from 2026).
A4: Commercial Vehicle Credit (2022 $) | B4: 40000
A5: Passenger Vehicle Credit (2022 $) | B5: 7500
A6: OBBBA availability factor (1=full, 0.75=2025, 0 from 2026) | B6: 1 | C6: 1 | D6: 0.75 | E6: 0 | F6: 0 | G6: 0 | H6: 0 | I6: 0 | J6: 0 | K6: 0
B7: 2023 | C7: 2024 | D7: 2025 | E7: 2026 | F7: 2027 | G7: 2028 | H7: 2029 | I7: 2030 | J7: 2031 | K7: 2032
A8: Psgr HDV (2012 $) | B8: =$B$4*$B$16*C$14*B$6 -> 25920.503 | C8: =$B$4*$B$16*D$14*C$6 -> 25177.91 | D8: =$B$4*$B$16*E$14*D$6 -> 18333.428 | E8: =$B$4*$B$16*F$14*E$6 -> 0 | F8: =$B$4*$B$16*G$14*F$6 -> 0 | G8: =$B$4*$B$16*H$14*G$6 -> 0 | H8: =$B$4*$B$16*I$14*H$6 -> 0 | I8: =$B$4*$B$16*J$14*I$6 -> 0 | ... K8: =$B$4*$B$16*L$14*K$6 -> 0
A9: Freight HDV (2012 $) | B9: =$B$4*C$14*B$6 -> 30140.12 | C9: =$B$4*D$14*C$6 -> 29276.64 | D9: =$B$4*E$14*D$6 -> 21317.94 | E9: =$B$4*F$14*E$6 -> 0 | F9: =$B$4*G$14*F$6 -> 0 | G9: =$B$4*H$14*G$6 -> 0 | H9: =$B$4*I$14*H$6 -> 0 | I9: =$B$4*J$14*I$6 -> 0 | ... K9: =$B$4*L$14*K$6 -> 0
A10: Frgt LDV (2012 $) | B10: =C36*B$6 -> 9715.0656 | C10: =D36*C$6 -> 9379.5012 | D10: =E36*D$6 -> 6823.6172 | E10: =F36*E$6 -> 0 | F10: =G36*F$6 -> 0 | G10: =H36*G$6 -> 0 | H10: =I36*H$6 -> 0 | I10: =J36*I$6 -> 0 | ... K10: =L36*K$6 -> 0
A12: Calculations:
B13: 2022 | C13: 2023 | D13: 2024 | E13: 2025 | F13: 2026 | G13: 2027 | H13: 2028 | I13: 2029 | J13: 2030 | K13: 2031 | L13: 2032
A14: Conversion to 2012$ | B14: {=TRANSPOSE('Passenger Vehicle Calculations'!G94:G104)} -> 0.784521 | C14: 0.753503 | D14: 0.731916 | E14: 0.710598 | F14: 0.689901 | G14: 0.669807 | H14: 0.650298 | I14: 0.631357 | J14: 0.612968 | K14: 0.595115 | L14: 0.577781
A16: Fraction of buses owned by private entities (see trans/FoVObE) | B16: 0.86
A19: The credit caps are $7,500 for vehicles under 14,000 lbs and $40,000 for vehicles over 14,000 lbs (class 4 and above). We need to calculate
A20: a weighted average credit for our freight LDV category, which includes vehicle classes 2b-6.
A22: AEO classifications (see AEO table footnotes) | B22: Class | C22: Weight | D22: Credit Amount (2012 $)
A23: Commercial light trucks | B23: 2b | C23: 8,501-10,000 lbs | D23: =B5*B14 -> 5883.9075
A24: Light Medium trucks | B24: 3 | C24: 10,001-14,000 lbs | D24: =D23 -> 5883.9075
A25: Medium trucks | B25: 44657 | C25: 14,001-26,000 lbs | D25: =B4*B14 -> 31380.84
A27: Weighted Average calculated relative to AEO sales
A28: Source: EIA AEO 2023, Tables 44 and 49
A29: Note (2026-06): row-14 deflators synced to US national BVS full precision. Commercial 45W credit ends after 2025 per OBBBA (row 6 factor); US national file is pre-OBBBA and was NOT adopted for the credit window.
A30: Sales (thousands)
A31: AEO 2023 | B31: 2022 | C31: 2023 | D31: 2024 | E31: 2025 | F31: 2026 | G31: 2027 | H31: 2028 | I31: 2029 | J31: 2030 | K31: 2031 | L31: 2032
A32: Total Commercial Light Truck Sales | B32: 652.15881 | C32: 675.13666 | D32: 689.60468 | E32: 691.51691 | F32: 688.42426 | G32: 684.18414 | H32: 682.62189 | I32: 679.86218 | J32: 678.07776 | K32: 677.36639 | L32: 675.92621
A33: Light Medium Subtotal | B33: 252.12297 | C33: 262.19943 | D33: 276.18127 | E33: 286.01892 | F33: 290.46655 | G33: 292.4324 | H33: 293.63425 | I33: 296.17325 | J33: 298.1217 | K33: 300.39685 | L33: 303.25729
A34: Medium Subtotal | B34: 180.61983 | C34: 186.4935 | D34: 188.82283 | E34: 190.62694 | F34: 195.10698 | G34: 202.50728 | H34: 207.00558 | I34: 207.12138 | J34: 203.82384 | K34: 201.78429 | L34: 203.63635
A36: Weighted Average Credit | B36: =SUMPRODUCT(B32:B34,$D$23:$D$25)/SUM(B32:B34) -> 10128.764 | C36: =SUMPRODUCT(C32:C34,$D$23:$D$25)/SUM(C32:C34)*C14/$B$14 -> 9715.0656 | D36: =SUMPRODUCT(D32:D34,$D$23:$D$25)/SUM(D32:D34)*D14/$B$14 -> 9379.5012 | E36: =SUMPRODUCT(E32:E34,$D$23:$D$25)/SUM(E32:E34)*E14/$B$14 -> 9098.1562 | F36: =SUMPRODUCT(F32:F34,$D$23:$D$25)/SUM(F32:F34)*F14/$B$14 -> 8900.539 | G36: =SUMPRODUCT(G32:G34,$D$23:$D$25)/SUM(G32:G34)*G14/$B$14 -> 8762.1978 | H36: =SUMPRODUCT(H32:H34,$D$23:$D$25)/SUM(H32:H34)*H14/$B$14 -> 8574.64 | I36: =SUMPRODUCT(I32:I34,$D$23:$D$25)/SUM(I32:I34)*I14/$B$14 -> 8327.2161 | J36: =SUMPRODUCT(J32:J34,$D$23:$D$25)/SUM(J32:J34)*J14/$B$14 -> 8038.267 | ... L36: =SUMPRODUCT(L32:L34,$D$23:$D$25)/SUM(L32:L34)*L14/$B$14 -> 7566.1909

Sheet psgr

Sheet BVS-psgr-LDVs
A1: Subsidy (2012 USD) | B1: 2021 | C1: 2022 | D1: 2023 | E1: 2024 | F1: 2025 | G1: 2026 | H1: 2027 | I1: 2028 | J1: 2029 | K1: 2030 | L1: 2031 | M1: 2032 | N1: 2033 | O1: 2034 | P1: 2035 | Q1: 2036 | R1: 2037 | S1: 2038 | T1: 2039 | U1: 2040 | V1: 2041 | W1: 2042 | X1: 2043 | Y1: 2044 | Z1: 2045 | AA1: 2046 | AB1: 2047 | AC1: 2048 | AD1: 2049 | AE1: 2050
A2: battery electric vehicle | B2: ='Passenger Vehicle Calculations'!C68 -> 1646.4981 | C2: ='Passenger Vehicle Calculations'!D68 -> 1368.5858 | D2: ='Passenger Vehicle Calculations'!E68 -> 4795.9637 | E2: ='Passenger Vehicle Calculations'!F68 -> 3555.4877 | F2: ='Passenger Vehicle Calculations'!G68 -> 2524.2658 | G2: ='Passenger Vehicle Calculations'!H68 -> 0 | H2: ='Passenger Vehicle Calculations'!I68 -> 0 | I2: ='Passenger Vehicle Calculations'!J68 -> 0 | ... AE2: ='Passenger Vehicle Calculations'!AF68 -> 0
A3: natural gas vehicle | B3: 0 | C3: 0 | D3: 0 | E3: 0 | F3: 0 | G3: 0 | H3: 0 | I3: 0 | J3: 0 | K3: 0 | L3: 0 | M3: 0 | N3: 0 | O3: 0 | P3: 0 | Q3: 0 | R3: 0 | S3: 0 | T3: 0 | U3: 0 | V3: 0 | W3: 0 | X3: 0 | Y3: 0 | Z3: 0 | AA3: 0 | AB3: 0 | AC3: 0 | AD3: 0 | AE3: 0
A4: gasoline vehicle | B4: 0 | C4: 0 | D4: 0 | E4: 0 | F4: 0 | G4: 0 | H4: 0 | I4: 0 | J4: 0 | K4: 0 | L4: 0 | M4: 0 | N4: 0 | O4: 0 | P4: 0 | Q4: 0 | R4: 0 | S4: 0 | T4: 0 | U4: 0 | V4: 0 | W4: 0 | X4: 0 | Y4: 0 | Z4: 0 | AA4: 0 | AB4: 0 | AC4: 0 | AD4: 0 | AE4: 0
A5: diesel vehicle | B5: 0 | C5: 0 | D5: 0 | E5: 0 | F5: 0 | G5: 0 | H5: 0 | I5: 0 | J5: 0 | K5: 0 | L5: 0 | M5: 0 | N5: 0 | O5: 0 | P5: 0 | Q5: 0 | R5: 0 | S5: 0 | T5: 0 | U5: 0 | V5: 0 | W5: 0 | X5: 0 | Y5: 0 | Z5: 0 | AA5: 0 | AB5: 0 | AC5: 0 | AD5: 0 | AE5: 0
A6: plugin hybrid vehicle | B6: ='Passenger Vehicle Calculations'!C69 -> 6652.7185 | C6: ='Passenger Vehicle Calculations'!D69 -> 3617.0507 | D6: ='Passenger Vehicle Calculations'!E69 -> 3481.1983 | E6: ='Passenger Vehicle Calculations'!F69 -> 2846.5223 | F6: ='Passenger Vehicle Calculations'!G69 -> 1797.1625 | G6: ='Passenger Vehicle Calculations'!H69 -> 0 | H6: ='Passenger Vehicle Calculations'!I69 -> 0 | I6: ='Passenger Vehicle Calculations'!J69 -> 0 | ... AE6: ='Passenger Vehicle Calculations'!AF69 -> 0
A7: LPG vehicle | B7: 0 | C7: 0 | D7: 0 | E7: 0 | F7: 0 | G7: 0 | H7: 0 | I7: 0 | J7: 0 | K7: 0 | L7: 0 | M7: 0 | N7: 0 | O7: 0 | P7: 0 | Q7: 0 | R7: 0 | S7: 0 | T7: 0 | U7: 0 | V7: 0 | W7: 0 | X7: 0 | Y7: 0 | Z7: 0 | AA7: 0 | AB7: 0 | AC7: 0 | AD7: 0 | AE7: 0
A8: hydrogen vehicle | B8: 0 | C8: 0 | D8: =D2 -> 4795.9637 | E8: =E2 -> 3555.4877 | F8: =F2 -> 2524.2658 | G8: =G2 -> 0 | H8: =H2 -> 0 | I8: =I2 -> 0 | J8: =J2 -> 0 | K8: =K2 -> 0 | ... AE8: =AE2 -> 0

Sheet BVS-psgr-HDVs
A1: Subsidy (2012 USD) | B1: 2021 | C1: 2022 | D1: 2023 | E1: 2024 | F1: 2025 | G1: 2026 | H1: 2027 | I1: 2028 | J1: 2029 | K1: 2030 | L1: 2031 | M1: 2032 | N1: 2033 | O1: 2034 | P1: 2035 | Q1: 2036 | R1: 2037 | S1: 2038 | T1: 2039 | U1: 2040 | V1: 2041 | W1: 2042 | X1: 2043 | Y1: 2044 | Z1: 2045 | AA1: 2046 | AB1: 2047 | AC1: 2048 | AD1: 2049 | AE1: 2050
A2: battery electric vehicle | B2: 0 | C2: 0 | D2: ='Commercial Vehicles'!$B4*'Commercial Vehicles'!C14*'Commercial Vehicles'!$B16 -> 25920.503 | E2: ='Commercial Vehicles'!$B4*'Commercial Vehicles'!D14*'Commercial Vehicles'!$B16 -> 25177.91 | F2: ='Commercial Vehicles'!$B4*'Commercial Vehicles'!E14*'Commercial Vehicles'!$B16 -> 24444.571 | G2: ='Commercial Vehicles'!$B4*'Commercial Vehicles'!F14*'Commercial Vehicles'!$B16 -> 23732.594 | H2: ='Commercial Vehicles'!$B4*'Commercial Vehicles'!G14*'Commercial Vehicles'!$B16 -> 23041.361 | I2: ='Commercial Vehicles'!$B4*'Commercial Vehicles'!H14*'Commercial Vehicles'!$B16 -> 22370.251 | J2: ='Commercial Vehicles'!$B4*'Commercial Vehicles'!I14*'Commercial Vehicles'!$B16 -> 21718.681 | K2: ='Commercial Vehicles'!$B4*'Commercial Vehicles'!J14*'Commercial Vehicles'!$B16 -> 21086.099 | ... M2: ='Commercial Vehicles'!$B4*'Commercial Vehicles'!L14*'Commercial Vehicles'!$B16 -> 19875.666 | N2: 0 | O2: 0 | P2: 0 | Q2: 0 | R2: 0 | S2: 0 | T2: 0 | U2: 0 | V2: 0 | W2: 0 | X2: 0 | Y2: 0 | Z2: 0 | AA2: 0 | AB2: 0 | AC2: 0 | AD2: 0 | AE2: 0
A3: natural gas vehicle | B3: 0 | C3: 0 | D3: 0 | E3: 0 | F3: 0 | G3: 0 | H3: 0 | I3: 0 | J3: 0 | K3: 0 | L3: 0 | M3: 0 | N3: 0 | O3: 0 | P3: 0 | Q3: 0 | R3: 0 | S3: 0 | T3: 0 | U3: 0 | V3: 0 | W3: 0 | X3: 0 | Y3: 0 | Z3: 0 | AA3: 0 | AB3: 0 | AC3: 0 | AD3: 0 | AE3: 0
A4: gasoline vehicle | B4: 0 | C4: 0 | D4: 0 | E4: 0 | F4: 0 | G4: 0 | H4: 0 | I4: 0 | J4: 0 | K4: 0 | L4: 0 | M4: 0 | N4: 0 | O4: 0 | P4: 0 | Q4: 0 | R4: 0 | S4: 0 | T4: 0 | U4: 0 | V4: 0 | W4: 0 | X4: 0 | Y4: 0 | Z4: 0 | AA4: 0 | AB4: 0 | AC4: 0 | AD4: 0 | AE4: 0
A5: diesel vehicle | B5: 0 | C5: 0 | D5: 0 | E5: 0 | F5: 0 | G5: 0 | H5: 0 | I5: 0 | J5: 0 | K5: 0 | L5: 0 | M5: 0 | N5: 0 | O5: 0 | P5: 0 | Q5: 0 | R5: 0 | S5: 0 | T5: 0 | U5: 0 | V5: 0 | W5: 0 | X5: 0 | Y5: 0 | Z5: 0 | AA5: 0 | AB5: 0 | AC5: 0 | AD5: 0 | AE5: 0
A6: plugin hybrid vehicle | B6: 0 | C6: 0 | D6: =D2 -> 25920.503 | E6: =E2 -> 25177.91 | F6: =F2 -> 24444.571 | G6: =G2 -> 23732.594 | H6: =H2 -> 23041.361 | I6: =I2 -> 22370.251 | J6: =J2 -> 21718.681 | K6: =K2 -> 21086.099 | ... M6: =M2 -> 19875.666 | N6: 0 | O6: 0 | P6: 0 | Q6: 0 | R6: 0 | S6: 0 | T6: 0 | U6: 0 | V6: 0 | W6: 0 | X6: 0 | Y6: 0 | Z6: 0 | AA6: 0 | AB6: 0 | AC6: 0 | AD6: 0 | AE6: 0
A7: LPG vehicle | B7: 0 | C7: 0 | D7: 0 | E7: 0 | F7: 0 | G7: 0 | H7: 0 | I7: 0 | J7: 0 | K7: 0 | L7: 0 | M7: 0 | N7: 0 | O7: 0 | P7: 0 | Q7: 0 | R7: 0 | S7: 0 | T7: 0 | U7: 0 | V7: 0 | W7: 0 | X7: 0 | Y7: 0 | Z7: 0 | AA7: 0 | AB7: 0 | AC7: 0 | AD7: 0 | AE7: 0
A8: hydrogen vehicle | B8: 0 | C8: 0 | D8: =D2 -> 25920.503 | E8: =E2 -> 25177.91 | F8: =F2 -> 24444.571 | G8: =G2 -> 23732.594 | H8: =H2 -> 23041.361 | I8: =I2 -> 22370.251 | J8: =J2 -> 21718.681 | K8: =K2 -> 21086.099 | ... M8: =M2 -> 19875.666 | N8: 0 | O8: 0 | P8: 0 | Q8: 0 | R8: 0 | S8: 0 | T8: 0 | U8: 0 | V8: 0 | W8: 0 | X8: 0 | Y8: 0 | Z8: 0 | AA8: 0 | AB8: 0 | AC8: 0 | AD8: 0 | AE8: 0

Sheet BVS-psgr-aircraft
A1: Subsidy (2012 USD) | B1: 2021 | C1: 2022 | D1: 2023 | E1: 2024 | F1: 2025 | G1: 2026 | H1: 2027 | I1: 2028 | J1: 2029 | K1: 2030 | L1: 2031 | M1: 2032 | N1: 2033 | O1: 2034 | P1: 2035 | Q1: 2036 | R1: 2037 | S1: 2038 | T1: 2039 | U1: 2040 | V1: 2041 | W1: 2042 | X1: 2043 | Y1: 2044 | Z1: 2045 | AA1: 2046 | AB1: 2047 | AC1: 2048 | AD1: 2049 | AE1: 2050
A2: battery electric vehicle | B2: 0 | C2: 0 | D2: 0 | E2: 0 | F2: 0 | G2: 0 | H2: 0 | I2: 0 | J2: 0 | K2: 0 | L2: 0 | M2: 0 | N2: 0 | O2: 0 | P2: 0 | Q2: 0 | R2: 0 | S2: 0 | T2: 0 | U2: 0 | V2: 0 | W2: 0 | X2: 0 | Y2: 0 | Z2: 0 | AA2: 0 | AB2: 0 | AC2: 0 | AD2: 0 | AE2: 0
A3: natural gas vehicle | B3: 0 | C3: 0 | D3: 0 | E3: 0 | F3: 0 | G3: 0 | H3: 0 | I3: 0 | J3: 0 | K3: 0 | L3: 0 | M3: 0 | N3: 0 | O3: 0 | P3: 0 | Q3: 0 | R3: 0 | S3: 0 | T3: 0 | U3: 0 | V3: 0 | W3: 0 | X3: 0 | Y3: 0 | Z3: 0 | AA3: 0 | AB3: 0 | AC3: 0 | AD3: 0 | AE3: 0
A4: gasoline vehicle | B4: 0 | C4: 0 | D4: 0 | E4: 0 | F4: 0 | G4: 0 | H4: 0 | I4: 0 | J4: 0 | K4: 0 | L4: 0 | M4: 0 | N4: 0 | O4: 0 | P4: 0 | Q4: 0 | R4: 0 | S4: 0 | T4: 0 | U4: 0 | V4: 0 | W4: 0 | X4: 0 | Y4: 0 | Z4: 0 | AA4: 0 | AB4: 0 | AC4: 0 | AD4: 0 | AE4: 0
A5: diesel vehicle | B5: 0 | C5: 0 | D5: 0 | E5: 0 | F5: 0 | G5: 0 | H5: 0 | I5: 0 | J5: 0 | K5: 0 | L5: 0 | M5: 0 | N5: 0 | O5: 0 | P5: 0 | Q5: 0 | R5: 0 | S5: 0 | T5: 0 | U5: 0 | V5: 0 | W5: 0 | X5: 0 | Y5: 0 | Z5: 0 | AA5: 0 | AB5: 0 | AC5: 0 | AD5: 0 | AE5: 0
A6: plugin hybrid vehicle | B6: 0 | C6: 0 | D6: 0 | E6: 0 | F6: 0 | G6: 0 | H6: 0 | I6: 0 | J6: 0 | K6: 0 | L6: 0 | M6: 0 | N6: 0 | O6: 0 | P6: 0 | Q6: 0 | R6: 0 | S6: 0 | T6: 0 | U6: 0 | V6: 0 | W6: 0 | X6: 0 | Y6: 0 | Z6: 0 | AA6: 0 | AB6: 0 | AC6: 0 | AD6: 0 | AE6: 0
A7: LPG vehicle | B7: 0 | C7: 0 | D7: 0 | E7: 0 | F7: 0 | G7: 0 | H7: 0 | I7: 0 | J7: 0 | K7: 0 | L7: 0 | M7: 0 | N7: 0 | O7: 0 | P7: 0 | Q7: 0 | R7: 0 | S7: 0 | T7: 0 | U7: 0 | V7: 0 | W7: 0 | X7: 0 | Y7: 0 | Z7: 0 | AA7: 0 | AB7: 0 | AC7: 0 | AD7: 0 | AE7: 0
A8: hydrogen vehicle | B8: 0 | C8: 0 | D8: 0 | E8: 0 | F8: 0 | G8: 0 | H8: 0 | I8: 0 | J8: 0 | K8: 0 | L8: 0 | M8: 0 | N8: 0 | O8: 0 | P8: 0 | Q8: 0 | R8: 0 | S8: 0 | T8: 0 | U8: 0 | V8: 0 | W8: 0 | X8: 0 | Y8: 0 | Z8: 0 | AA8: 0 | AB8: 0 | AC8: 0 | AD8: 0 | AE8: 0

Sheet BVS-psgr-rail
A1: Subsidy (2012 USD) | B1: 2021 | C1: 2022 | D1: 2023 | E1: 2024 | F1: 2025 | G1: 2026 | H1: 2027 | I1: 2028 | J1: 2029 | K1: 2030 | L1: 2031 | M1: 2032 | N1: 2033 | O1: 2034 | P1: 2035 | Q1: 2036 | R1: 2037 | S1: 2038 | T1: 2039 | U1: 2040 | V1: 2041 | W1: 2042 | X1: 2043 | Y1: 2044 | Z1: 2045 | AA1: 2046 | AB1: 2047 | AC1: 2048 | AD1: 2049 | AE1: 2050
A2: battery electric vehicle | B2: 0 | C2: 0 | D2: 0 | E2: 0 | F2: 0 | G2: 0 | H2: 0 | I2: 0 | J2: 0 | K2: 0 | L2: 0 | M2: 0 | N2: 0 | O2: 0 | P2: 0 | Q2: 0 | R2: 0 | S2: 0 | T2: 0 | U2: 0 | V2: 0 | W2: 0 | X2: 0 | Y2: 0 | Z2: 0 | AA2: 0 | AB2: 0 | AC2: 0 | AD2: 0 | AE2: 0
A3: natural gas vehicle | B3: 0 | C3: 0 | D3: 0 | E3: 0 | F3: 0 | G3: 0 | H3: 0 | I3: 0 | J3: 0 | K3: 0 | L3: 0 | M3: 0 | N3: 0 | O3: 0 | P3: 0 | Q3: 0 | R3: 0 | S3: 0 | T3: 0 | U3: 0 | V3: 0 | W3: 0 | X3: 0 | Y3: 0 | Z3: 0 | AA3: 0 | AB3: 0 | AC3: 0 | AD3: 0 | AE3: 0
A4: gasoline vehicle | B4: 0 | C4: 0 | D4: 0 | E4: 0 | F4: 0 | G4: 0 | H4: 0 | I4: 0 | J4: 0 | K4: 0 | L4: 0 | M4: 0 | N4: 0 | O4: 0 | P4: 0 | Q4: 0 | R4: 0 | S4: 0 | T4: 0 | U4: 0 | V4: 0 | W4: 0 | X4: 0 | Y4: 0 | Z4: 0 | AA4: 0 | AB4: 0 | AC4: 0 | AD4: 0 | AE4: 0
A5: diesel vehicle | B5: 0 | C5: 0 | D5: 0 | E5: 0 | F5: 0 | G5: 0 | H5: 0 | I5: 0 | J5: 0 | K5: 0 | L5: 0 | M5: 0 | N5: 0 | O5: 0 | P5: 0 | Q5: 0 | R5: 0 | S5: 0 | T5: 0 | U5: 0 | V5: 0 | W5: 0 | X5: 0 | Y5: 0 | Z5: 0 | AA5: 0 | AB5: 0 | AC5: 0 | AD5: 0 | AE5: 0
A6: plugin hybrid vehicle | B6: 0 | C6: 0 | D6: 0 | E6: 0 | F6: 0 | G6: 0 | H6: 0 | I6: 0 | J6: 0 | K6: 0 | L6: 0 | M6: 0 | N6: 0 | O6: 0 | P6: 0 | Q6: 0 | R6: 0 | S6: 0 | T6: 0 | U6: 0 | V6: 0 | W6: 0 | X6: 0 | Y6: 0 | Z6: 0 | AA6: 0 | AB6: 0 | AC6: 0 | AD6: 0 | AE6: 0
A7: LPG vehicle | B7: 0 | C7: 0 | D7: 0 | E7: 0 | F7: 0 | G7: 0 | H7: 0 | I7: 0 | J7: 0 | K7: 0 | L7: 0 | M7: 0 | N7: 0 | O7: 0 | P7: 0 | Q7: 0 | R7: 0 | S7: 0 | T7: 0 | U7: 0 | V7: 0 | W7: 0 | X7: 0 | Y7: 0 | Z7: 0 | AA7: 0 | AB7: 0 | AC7: 0 | AD7: 0 | AE7: 0
A8: hydrogen vehicle | B8: 0 | C8: 0 | D8: 0 | E8: 0 | F8: 0 | G8: 0 | H8: 0 | I8: 0 | J8: 0 | K8: 0 | L8: 0 | M8: 0 | N8: 0 | O8: 0 | P8: 0 | Q8: 0 | R8: 0 | S8: 0 | T8: 0 | U8: 0 | V8: 0 | W8: 0 | X8: 0 | Y8: 0 | Z8: 0 | AA8: 0 | AB8: 0 | AC8: 0 | AD8: 0 | AE8: 0

Sheet BVS-psgr-ships
A1: Subsidy (2012 USD) | B1: 2021 | C1: 2022 | D1: 2023 | E1: 2024 | F1: 2025 | G1: 2026 | H1: 2027 | I1: 2028 | J1: 2029 | K1: 2030 | L1: 2031 | M1: 2032 | N1: 2033 | O1: 2034 | P1: 2035 | Q1: 2036 | R1: 2037 | S1: 2038 | T1: 2039 | U1: 2040 | V1: 2041 | W1: 2042 | X1: 2043 | Y1: 2044 | Z1: 2045 | AA1: 2046 | AB1: 2047 | AC1: 2048 | AD1: 2049 | AE1: 2050
A2: battery electric vehicle | B2: 0 | C2: 0 | D2: 0 | E2: 0 | F2: 0 | G2: 0 | H2: 0 | I2: 0 | J2: 0 | K2: 0 | L2: 0 | M2: 0 | N2: 0 | O2: 0 | P2: 0 | Q2: 0 | R2: 0 | S2: 0 | T2: 0 | U2: 0 | V2: 0 | W2: 0 | X2: 0 | Y2: 0 | Z2: 0 | AA2: 0 | AB2: 0 | AC2: 0 | AD2: 0 | AE2: 0
A3: natural gas vehicle | B3: 0 | C3: 0 | D3: 0 | E3: 0 | F3: 0 | G3: 0 | H3: 0 | I3: 0 | J3: 0 | K3: 0 | L3: 0 | M3: 0 | N3: 0 | O3: 0 | P3: 0 | Q3: 0 | R3: 0 | S3: 0 | T3: 0 | U3: 0 | V3: 0 | W3: 0 | X3: 0 | Y3: 0 | Z3: 0 | AA3: 0 | AB3: 0 | AC3: 0 | AD3: 0 | AE3: 0
A4: gasoline vehicle | B4: 0 | C4: 0 | D4: 0 | E4: 0 | F4: 0 | G4: 0 | H4: 0 | I4: 0 | J4: 0 | K4: 0 | L4: 0 | M4: 0 | N4: 0 | O4: 0 | P4: 0 | Q4: 0 | R4: 0 | S4: 0 | T4: 0 | U4: 0 | V4: 0 | W4: 0 | X4: 0 | Y4: 0 | Z4: 0 | AA4: 0 | AB4: 0 | AC4: 0 | AD4: 0 | AE4: 0
A5: diesel vehicle | B5: 0 | C5: 0 | D5: 0 | E5: 0 | F5: 0 | G5: 0 | H5: 0 | I5: 0 | J5: 0 | K5: 0 | L5: 0 | M5: 0 | N5: 0 | O5: 0 | P5: 0 | Q5: 0 | R5: 0 | S5: 0 | T5: 0 | U5: 0 | V5: 0 | W5: 0 | X5: 0 | Y5: 0 | Z5: 0 | AA5: 0 | AB5: 0 | AC5: 0 | AD5: 0 | AE5: 0
A6: plugin hybrid vehicle | B6: 0 | C6: 0 | D6: 0 | E6: 0 | F6: 0 | G6: 0 | H6: 0 | I6: 0 | J6: 0 | K6: 0 | L6: 0 | M6: 0 | N6: 0 | O6: 0 | P6: 0 | Q6: 0 | R6: 0 | S6: 0 | T6: 0 | U6: 0 | V6: 0 | W6: 0 | X6: 0 | Y6: 0 | Z6: 0 | AA6: 0 | AB6: 0 | AC6: 0 | AD6: 0 | AE6: 0
A7: LPG vehicle | B7: 0 | C7: 0 | D7: 0 | E7: 0 | F7: 0 | G7: 0 | H7: 0 | I7: 0 | J7: 0 | K7: 0 | L7: 0 | M7: 0 | N7: 0 | O7: 0 | P7: 0 | Q7: 0 | R7: 0 | S7: 0 | T7: 0 | U7: 0 | V7: 0 | W7: 0 | X7: 0 | Y7: 0 | Z7: 0 | AA7: 0 | AB7: 0 | AC7: 0 | AD7: 0 | AE7: 0
A8: hydrogen vehicle | B8: 0 | C8: 0 | D8: 0 | E8: 0 | F8: 0 | G8: 0 | H8: 0 | I8: 0 | J8: 0 | K8: 0 | L8: 0 | M8: 0 | N8: 0 | O8: 0 | P8: 0 | Q8: 0 | R8: 0 | S8: 0 | T8: 0 | U8: 0 | V8: 0 | W8: 0 | X8: 0 | Y8: 0 | Z8: 0 | AA8: 0 | AB8: 0 | AC8: 0 | AD8: 0 | AE8: 0

Sheet BVS-psgr-motorbikes
A1: Subsidy (2012 USD) | B1: 2021 | C1: 2022 | D1: 2023 | E1: 2024 | F1: 2025 | G1: 2026 | H1: 2027 | I1: 2028 | J1: 2029 | K1: 2030 | L1: 2031 | M1: 2032 | N1: 2033 | O1: 2034 | P1: 2035 | Q1: 2036 | R1: 2037 | S1: 2038 | T1: 2039 | U1: 2040 | V1: 2041 | W1: 2042 | X1: 2043 | Y1: 2044 | Z1: 2045 | AA1: 2046 | AB1: 2047 | AC1: 2048 | AD1: 2049 | AE1: 2050
A2: battery electric vehicle | B2: 0 | C2: 0 | D2: 0 | E2: 0 | F2: 0 | G2: 0 | H2: 0 | I2: 0 | J2: 0 | K2: 0 | L2: 0 | M2: 0 | N2: 0 | O2: 0 | P2: 0 | Q2: 0 | R2: 0 | S2: 0 | T2: 0 | U2: 0 | V2: 0 | W2: 0 | X2: 0 | Y2: 0 | Z2: 0 | AA2: 0 | AB2: 0 | AC2: 0 | AD2: 0 | AE2: 0
A3: natural gas vehicle | B3: 0 | C3: 0 | D3: 0 | E3: 0 | F3: 0 | G3: 0 | H3: 0 | I3: 0 | J3: 0 | K3: 0 | L3: 0 | M3: 0 | N3: 0 | O3: 0 | P3: 0 | Q3: 0 | R3: 0 | S3: 0 | T3: 0 | U3: 0 | V3: 0 | W3: 0 | X3: 0 | Y3: 0 | Z3: 0 | AA3: 0 | AB3: 0 | AC3: 0 | AD3: 0 | AE3: 0
A4: gasoline vehicle | B4: 0 | C4: 0 | D4: 0 | E4: 0 | F4: 0 | G4: 0 | H4: 0 | I4: 0 | J4: 0 | K4: 0 | L4: 0 | M4: 0 | N4: 0 | O4: 0 | P4: 0 | Q4: 0 | R4: 0 | S4: 0 | T4: 0 | U4: 0 | V4: 0 | W4: 0 | X4: 0 | Y4: 0 | Z4: 0 | AA4: 0 | AB4: 0 | AC4: 0 | AD4: 0 | AE4: 0
A5: diesel vehicle | B5: 0 | C5: 0 | D5: 0 | E5: 0 | F5: 0 | G5: 0 | H5: 0 | I5: 0 | J5: 0 | K5: 0 | L5: 0 | M5: 0 | N5: 0 | O5: 0 | P5: 0 | Q5: 0 | R5: 0 | S5: 0 | T5: 0 | U5: 0 | V5: 0 | W5: 0 | X5: 0 | Y5: 0 | Z5: 0 | AA5: 0 | AB5: 0 | AC5: 0 | AD5: 0 | AE5: 0
A6: plugin hybrid vehicle | B6: 0 | C6: 0 | D6: 0 | E6: 0 | F6: 0 | G6: 0 | H6: 0 | I6: 0 | J6: 0 | K6: 0 | L6: 0 | M6: 0 | N6: 0 | O6: 0 | P6: 0 | Q6: 0 | R6: 0 | S6: 0 | T6: 0 | U6: 0 | V6: 0 | W6: 0 | X6: 0 | Y6: 0 | Z6: 0 | AA6: 0 | AB6: 0 | AC6: 0 | AD6: 0 | AE6: 0
A7: LPG vehicle | B7: 0 | C7: 0 | D7: 0 | E7: 0 | F7: 0 | G7: 0 | H7: 0 | I7: 0 | J7: 0 | K7: 0 | L7: 0 | M7: 0 | N7: 0 | O7: 0 | P7: 0 | Q7: 0 | R7: 0 | S7: 0 | T7: 0 | U7: 0 | V7: 0 | W7: 0 | X7: 0 | Y7: 0 | Z7: 0 | AA7: 0 | AB7: 0 | AC7: 0 | AD7: 0 | AE7: 0
A8: hydrogen vehicle | B8: 0 | C8: 0 | D8: 0 | E8: 0 | F8: 0 | G8: 0 | H8: 0 | I8: 0 | J8: 0 | K8: 0 | L8: 0 | M8: 0 | N8: 0 | O8: 0 | P8: 0 | Q8: 0 | R8: 0 | S8: 0 | T8: 0 | U8: 0 | V8: 0 | W8: 0 | X8: 0 | Y8: 0 | Z8: 0 | AA8: 0 | AB8: 0 | AC8: 0 | AD8: 0 | AE8: 0

Sheet frgt

Sheet BVS-frgt-LDVs
A1: Subsidy (2012 USD) | B1: 2021 | C1: 2022 | D1: 2023 | E1: 2024 | F1: 2025 | G1: 2026 | H1: 2027 | I1: 2028 | J1: 2029 | K1: 2030 | L1: 2031 | M1: 2032 | N1: 2033 | O1: 2034 | P1: 2035 | Q1: 2036 | R1: 2037 | S1: 2038 | T1: 2039 | U1: 2040 | V1: 2041 | W1: 2042 | X1: 2043 | Y1: 2044 | Z1: 2045 | AA1: 2046 | AB1: 2047 | AC1: 2048 | AD1: 2049 | AE1: 2050
A2: battery electric vehicle | B2: 0 | C2: 0 | D2: ='Commercial Vehicles'!B10 -> 9715.0656 | E2: ='Commercial Vehicles'!C10 -> 9379.5012 | F2: ='Commercial Vehicles'!D10 -> 6823.6172 | G2: ='Commercial Vehicles'!E10 -> 0 | H2: ='Commercial Vehicles'!F10 -> 0 | I2: ='Commercial Vehicles'!G10 -> 0 | J2: ='Commercial Vehicles'!H10 -> 0 | K2: ='Commercial Vehicles'!I10 -> 0 | ... M2: ='Commercial Vehicles'!K10 -> 0 | N2: 0 | O2: 0 | P2: 0 | Q2: 0 | R2: 0 | S2: 0 | T2: 0 | U2: 0 | V2: 0 | W2: 0 | X2: 0 | Y2: 0 | Z2: 0 | AA2: 0 | AB2: 0 | AC2: 0 | AD2: 0 | AE2: 0
A3: natural gas vehicle | B3: 0 | C3: 0 | D3: 0 | E3: 0 | F3: 0 | G3: 0 | H3: 0 | I3: 0 | J3: 0 | K3: 0 | L3: 0 | M3: 0 | N3: 0 | O3: 0 | P3: 0 | Q3: 0 | R3: 0 | S3: 0 | T3: 0 | U3: 0 | V3: 0 | W3: 0 | X3: 0 | Y3: 0 | Z3: 0 | AA3: 0 | AB3: 0 | AC3: 0 | AD3: 0 | AE3: 0
A4: gasoline vehicle | B4: 0 | C4: 0 | D4: 0 | E4: 0 | F4: 0 | G4: 0 | H4: 0 | I4: 0 | J4: 0 | K4: 0 | L4: 0 | M4: 0 | N4: 0 | O4: 0 | P4: 0 | Q4: 0 | R4: 0 | S4: 0 | T4: 0 | U4: 0 | V4: 0 | W4: 0 | X4: 0 | Y4: 0 | Z4: 0 | AA4: 0 | AB4: 0 | AC4: 0 | AD4: 0 | AE4: 0
A5: diesel vehicle | B5: 0 | C5: 0 | D5: 0 | E5: 0 | F5: 0 | G5: 0 | H5: 0 | I5: 0 | J5: 0 | K5: 0 | L5: 0 | M5: 0 | N5: 0 | O5: 0 | P5: 0 | Q5: 0 | R5: 0 | S5: 0 | T5: 0 | U5: 0 | V5: 0 | W5: 0 | X5: 0 | Y5: 0 | Z5: 0 | AA5: 0 | AB5: 0 | AC5: 0 | AD5: 0 | AE5: 0
A6: plugin hybrid vehicle | B6: 0 | C6: 0 | D6: =D2 -> 9715.0656 | E6: =E2 -> 9379.5012 | F6: =F2 -> 6823.6172 | G6: =G2 -> 0 | H6: =H2 -> 0 | I6: =I2 -> 0 | J6: =J2 -> 0 | K6: =K2 -> 0 | ... M6: =M2 -> 0 | N6: 0 | O6: 0 | P6: 0 | Q6: 0 | R6: 0 | S6: 0 | T6: 0 | U6: 0 | V6: 0 | W6: 0 | X6: 0 | Y6: 0 | Z6: 0 | AA6: 0 | AB6: 0 | AC6: 0 | AD6: 0 | AE6: 0
A7: LPG vehicle | B7: 0 | C7: 0 | D7: 0 | E7: 0 | F7: 0 | G7: 0 | H7: 0 | I7: 0 | J7: 0 | K7: 0 | L7: 0 | M7: 0 | N7: 0 | O7: 0 | P7: 0 | Q7: 0 | R7: 0 | S7: 0 | T7: 0 | U7: 0 | V7: 0 | W7: 0 | X7: 0 | Y7: 0 | Z7: 0 | AA7: 0 | AB7: 0 | AC7: 0 | AD7: 0 | AE7: 0
A8: hydrogen vehicle | B8: 0 | C8: 0 | D8: =D2 -> 9715.0656 | E8: =E2 -> 9379.5012 | F8: =F2 -> 6823.6172 | G8: =G2 -> 0 | H8: =H2 -> 0 | I8: =I2 -> 0 | J8: =J2 -> 0 | K8: =K2 -> 0 | ... M8: =M2 -> 0 | N8: 0 | O8: 0 | P8: 0 | Q8: 0 | R8: 0 | S8: 0 | T8: 0 | U8: 0 | V8: 0 | W8: 0 | X8: 0 | Y8: 0 | Z8: 0 | AA8: 0 | AB8: 0 | AC8: 0 | AD8: 0 | AE8: 0

Sheet BVS-frgt-HDVs
A1: Subsidy (2012 USD) | B1: 2021 | C1: 2022 | D1: 2023 | E1: 2024 | F1: 2025 | G1: 2026 | H1: 2027 | I1: 2028 | J1: 2029 | K1: 2030 | L1: 2031 | M1: 2032 | N1: 2033 | O1: 2034 | P1: 2035 | Q1: 2036 | R1: 2037 | S1: 2038 | T1: 2039 | U1: 2040 | V1: 2041 | W1: 2042 | X1: 2043 | Y1: 2044 | Z1: 2045 | AA1: 2046 | AB1: 2047 | AC1: 2048 | AD1: 2049 | AE1: 2050
A2: battery electric vehicle | B2: 0 | C2: 0 | D2: ='Commercial Vehicles'!$B4*'Commercial Vehicles'!C14 -> 30140.12 | E2: ='Commercial Vehicles'!$B4*'Commercial Vehicles'!D14 -> 29276.64 | F2: ='Commercial Vehicles'!$B4*'Commercial Vehicles'!E14 -> 28423.92 | G2: ='Commercial Vehicles'!$B4*'Commercial Vehicles'!F14 -> 27596.04 | H2: ='Commercial Vehicles'!$B4*'Commercial Vehicles'!G14 -> 26792.28 | I2: ='Commercial Vehicles'!$B4*'Commercial Vehicles'!H14 -> 26011.92 | J2: ='Commercial Vehicles'!$B4*'Commercial Vehicles'!I14 -> 25254.28 | K2: ='Commercial Vehicles'!$B4*'Commercial Vehicles'!J14 -> 24518.72 | ... M2: ='Commercial Vehicles'!$B4*'Commercial Vehicles'!L14 -> 23111.24 | N2: 0 | O2: 0 | P2: 0 | Q2: 0 | R2: 0 | S2: 0 | T2: 0 | U2: 0 | V2: 0 | W2: 0 | X2: 0 | Y2: 0 | Z2: 0 | AA2: 0 | AB2: 0 | AC2: 0 | AD2: 0 | AE2: 0
A3: natural gas vehicle | B3: 0 | C3: 0 | D3: 0 | E3: 0 | F3: 0 | G3: 0 | H3: 0 | I3: 0 | J3: 0 | K3: 0 | L3: 0 | M3: 0 | N3: 0 | O3: 0 | P3: 0 | Q3: 0 | R3: 0 | S3: 0 | T3: 0 | U3: 0 | V3: 0 | W3: 0 | X3: 0 | Y3: 0 | Z3: 0 | AA3: 0 | AB3: 0 | AC3: 0 | AD3: 0 | AE3: 0
A4: gasoline vehicle | B4: 0 | C4: 0 | D4: 0 | E4: 0 | F4: 0 | G4: 0 | H4: 0 | I4: 0 | J4: 0 | K4: 0 | L4: 0 | M4: 0 | N4: 0 | O4: 0 | P4: 0 | Q4: 0 | R4: 0 | S4: 0 | T4: 0 | U4: 0 | V4: 0 | W4: 0 | X4: 0 | Y4: 0 | Z4: 0 | AA4: 0 | AB4: 0 | AC4: 0 | AD4: 0 | AE4: 0
A5: diesel vehicle | B5: 0 | C5: 0 | D5: 0 | E5: 0 | F5: 0 | G5: 0 | H5: 0 | I5: 0 | J5: 0 | K5: 0 | L5: 0 | M5: 0 | N5: 0 | O5: 0 | P5: 0 | Q5: 0 | R5: 0 | S5: 0 | T5: 0 | U5: 0 | V5: 0 | W5: 0 | X5: 0 | Y5: 0 | Z5: 0 | AA5: 0 | AB5: 0 | AC5: 0 | AD5: 0 | AE5: 0
A6: plugin hybrid vehicle | B6: 0 | C6: 0 | D6: =D2 -> 30140.12 | E6: =E2 -> 29276.64 | F6: =F2 -> 28423.92 | G6: =G2 -> 27596.04 | H6: =H2 -> 26792.28 | I6: =I2 -> 26011.92 | J6: =J2 -> 25254.28 | K6: =K2 -> 24518.72 | ... M6: =M2 -> 23111.24 | N6: 0 | O6: 0 | P6: 0 | Q6: 0 | R6: 0 | S6: 0 | T6: 0 | U6: 0 | V6: 0 | W6: 0 | X6: 0 | Y6: 0 | Z6: 0 | AA6: 0 | AB6: 0 | AC6: 0 | AD6: 0 | AE6: 0
A7: LPG vehicle | B7: 0 | C7: 0 | D7: 0 | E7: 0 | F7: 0 | G7: 0 | H7: 0 | I7: 0 | J7: 0 | K7: 0 | L7: 0 | M7: 0 | N7: 0 | O7: 0 | P7: 0 | Q7: 0 | R7: 0 | S7: 0 | T7: 0 | U7: 0 | V7: 0 | W7: 0 | X7: 0 | Y7: 0 | Z7: 0 | AA7: 0 | AB7: 0 | AC7: 0 | AD7: 0 | AE7: 0
A8: hydrogen vehicle | B8: 0 | C8: 0 | D8: =D2 -> 30140.12 | E8: =E2 -> 29276.64 | F8: =F2 -> 28423.92 | G8: =G2 -> 27596.04 | H8: =H2 -> 26792.28 | I8: =I2 -> 26011.92 | J8: =J2 -> 25254.28 | K8: =K2 -> 24518.72 | ... M8: =M2 -> 23111.24 | N8: 0 | O8: 0 | P8: 0 | Q8: 0 | R8: 0 | S8: 0 | T8: 0 | U8: 0 | V8: 0 | W8: 0 | X8: 0 | Y8: 0 | Z8: 0 | AA8: 0 | AB8: 0 | AC8: 0 | AD8: 0 | AE8: 0

Sheet BVS-frgt-aircraft
A1: Subsidy (2012 USD) | B1: 2021 | C1: 2022 | D1: 2023 | E1: 2024 | F1: 2025 | G1: 2026 | H1: 2027 | I1: 2028 | J1: 2029 | K1: 2030 | L1: 2031 | M1: 2032 | N1: 2033 | O1: 2034 | P1: 2035 | Q1: 2036 | R1: 2037 | S1: 2038 | T1: 2039 | U1: 2040 | V1: 2041 | W1: 2042 | X1: 2043 | Y1: 2044 | Z1: 2045 | AA1: 2046 | AB1: 2047 | AC1: 2048 | AD1: 2049 | AE1: 2050
A2: battery electric vehicle | B2: 0 | C2: 0 | D2: 0 | E2: 0 | F2: 0 | G2: 0 | H2: 0 | I2: 0 | J2: 0 | K2: 0 | L2: 0 | M2: 0 | N2: 0 | O2: 0 | P2: 0 | Q2: 0 | R2: 0 | S2: 0 | T2: 0 | U2: 0 | V2: 0 | W2: 0 | X2: 0 | Y2: 0 | Z2: 0 | AA2: 0 | AB2: 0 | AC2: 0 | AD2: 0 | AE2: 0
A3: natural gas vehicle | B3: 0 | C3: 0 | D3: 0 | E3: 0 | F3: 0 | G3: 0 | H3: 0 | I3: 0 | J3: 0 | K3: 0 | L3: 0 | M3: 0 | N3: 0 | O3: 0 | P3: 0 | Q3: 0 | R3: 0 | S3: 0 | T3: 0 | U3: 0 | V3: 0 | W3: 0 | X3: 0 | Y3: 0 | Z3: 0 | AA3: 0 | AB3: 0 | AC3: 0 | AD3: 0 | AE3: 0
A4: gasoline vehicle | B4: 0 | C4: 0 | D4: 0 | E4: 0 | F4: 0 | G4: 0 | H4: 0 | I4: 0 | J4: 0 | K4: 0 | L4: 0 | M4: 0 | N4: 0 | O4: 0 | P4: 0 | Q4: 0 | R4: 0 | S4: 0 | T4: 0 | U4: 0 | V4: 0 | W4: 0 | X4: 0 | Y4: 0 | Z4: 0 | AA4: 0 | AB4: 0 | AC4: 0 | AD4: 0 | AE4: 0
A5: diesel vehicle | B5: 0 | C5: 0 | D5: 0 | E5: 0 | F5: 0 | G5: 0 | H5: 0 | I5: 0 | J5: 0 | K5: 0 | L5: 0 | M5: 0 | N5: 0 | O5: 0 | P5: 0 | Q5: 0 | R5: 0 | S5: 0 | T5: 0 | U5: 0 | V5: 0 | W5: 0 | X5: 0 | Y5: 0 | Z5: 0 | AA5: 0 | AB5: 0 | AC5: 0 | AD5: 0 | AE5: 0
A6: plugin hybrid vehicle | B6: 0 | C6: 0 | D6: 0 | E6: 0 | F6: 0 | G6: 0 | H6: 0 | I6: 0 | J6: 0 | K6: 0 | L6: 0 | M6: 0 | N6: 0 | O6: 0 | P6: 0 | Q6: 0 | R6: 0 | S6: 0 | T6: 0 | U6: 0 | V6: 0 | W6: 0 | X6: 0 | Y6: 0 | Z6: 0 | AA6: 0 | AB6: 0 | AC6: 0 | AD6: 0 | AE6: 0
A7: LPG vehicle | B7: 0 | C7: 0 | D7: 0 | E7: 0 | F7: 0 | G7: 0 | H7: 0 | I7: 0 | J7: 0 | K7: 0 | L7: 0 | M7: 0 | N7: 0 | O7: 0 | P7: 0 | Q7: 0 | R7: 0 | S7: 0 | T7: 0 | U7: 0 | V7: 0 | W7: 0 | X7: 0 | Y7: 0 | Z7: 0 | AA7: 0 | AB7: 0 | AC7: 0 | AD7: 0 | AE7: 0
A8: hydrogen vehicle | B8: 0 | C8: 0 | D8: 0 | E8: 0 | F8: 0 | G8: 0 | H8: 0 | I8: 0 | J8: 0 | K8: 0 | L8: 0 | M8: 0 | N8: 0 | O8: 0 | P8: 0 | Q8: 0 | R8: 0 | S8: 0 | T8: 0 | U8: 0 | V8: 0 | W8: 0 | X8: 0 | Y8: 0 | Z8: 0 | AA8: 0 | AB8: 0 | AC8: 0 | AD8: 0 | AE8: 0

Sheet BVS-frgt-rail
A1: Subsidy (2012 USD) | B1: 2021 | C1: 2022 | D1: 2023 | E1: 2024 | F1: 2025 | G1: 2026 | H1: 2027 | I1: 2028 | J1: 2029 | K1: 2030 | L1: 2031 | M1: 2032 | N1: 2033 | O1: 2034 | P1: 2035 | Q1: 2036 | R1: 2037 | S1: 2038 | T1: 2039 | U1: 2040 | V1: 2041 | W1: 2042 | X1: 2043 | Y1: 2044 | Z1: 2045 | AA1: 2046 | AB1: 2047 | AC1: 2048 | AD1: 2049 | AE1: 2050
A2: battery electric vehicle | B2: 0 | C2: 0 | D2: 0 | E2: 0 | F2: 0 | G2: 0 | H2: 0 | I2: 0 | J2: 0 | K2: 0 | L2: 0 | M2: 0 | N2: 0 | O2: 0 | P2: 0 | Q2: 0 | R2: 0 | S2: 0 | T2: 0 | U2: 0 | V2: 0 | W2: 0 | X2: 0 | Y2: 0 | Z2: 0 | AA2: 0 | AB2: 0 | AC2: 0 | AD2: 0 | AE2: 0
A3: natural gas vehicle | B3: 0 | C3: 0 | D3: 0 | E3: 0 | F3: 0 | G3: 0 | H3: 0 | I3: 0 | J3: 0 | K3: 0 | L3: 0 | M3: 0 | N3: 0 | O3: 0 | P3: 0 | Q3: 0 | R3: 0 | S3: 0 | T3: 0 | U3: 0 | V3: 0 | W3: 0 | X3: 0 | Y3: 0 | Z3: 0 | AA3: 0 | AB3: 0 | AC3: 0 | AD3: 0 | AE3: 0
A4: gasoline vehicle | B4: 0 | C4: 0 | D4: 0 | E4: 0 | F4: 0 | G4: 0 | H4: 0 | I4: 0 | J4: 0 | K4: 0 | L4: 0 | M4: 0 | N4: 0 | O4: 0 | P4: 0 | Q4: 0 | R4: 0 | S4: 0 | T4: 0 | U4: 0 | V4: 0 | W4: 0 | X4: 0 | Y4: 0 | Z4: 0 | AA4: 0 | AB4: 0 | AC4: 0 | AD4: 0 | AE4: 0
A5: diesel vehicle | B5: 0 | C5: 0 | D5: 0 | E5: 0 | F5: 0 | G5: 0 | H5: 0 | I5: 0 | J5: 0 | K5: 0 | L5: 0 | M5: 0 | N5: 0 | O5: 0 | P5: 0 | Q5: 0 | R5: 0 | S5: 0 | T5: 0 | U5: 0 | V5: 0 | W5: 0 | X5: 0 | Y5: 0 | Z5: 0 | AA5: 0 | AB5: 0 | AC5: 0 | AD5: 0 | AE5: 0
A6: plugin hybrid vehicle | B6: 0 | C6: 0 | D6: 0 | E6: 0 | F6: 0 | G6: 0 | H6: 0 | I6: 0 | J6: 0 | K6: 0 | L6: 0 | M6: 0 | N6: 0 | O6: 0 | P6: 0 | Q6: 0 | R6: 0 | S6: 0 | T6: 0 | U6: 0 | V6: 0 | W6: 0 | X6: 0 | Y6: 0 | Z6: 0 | AA6: 0 | AB6: 0 | AC6: 0 | AD6: 0 | AE6: 0
A7: LPG vehicle | B7: 0 | C7: 0 | D7: 0 | E7: 0 | F7: 0 | G7: 0 | H7: 0 | I7: 0 | J7: 0 | K7: 0 | L7: 0 | M7: 0 | N7: 0 | O7: 0 | P7: 0 | Q7: 0 | R7: 0 | S7: 0 | T7: 0 | U7: 0 | V7: 0 | W7: 0 | X7: 0 | Y7: 0 | Z7: 0 | AA7: 0 | AB7: 0 | AC7: 0 | AD7: 0 | AE7: 0
A8: hydrogen vehicle | B8: 0 | C8: 0 | D8: 0 | E8: 0 | F8: 0 | G8: 0 | H8: 0 | I8: 0 | J8: 0 | K8: 0 | L8: 0 | M8: 0 | N8: 0 | O8: 0 | P8: 0 | Q8: 0 | R8: 0 | S8: 0 | T8: 0 | U8: 0 | V8: 0 | W8: 0 | X8: 0 | Y8: 0 | Z8: 0 | AA8: 0 | AB8: 0 | AC8: 0 | AD8: 0 | AE8: 0

Sheet BVS-frgt-ships
A1: Subsidy (2012 USD) | B1: 2021 | C1: 2022 | D1: 2023 | E1: 2024 | F1: 2025 | G1: 2026 | H1: 2027 | I1: 2028 | J1: 2029 | K1: 2030 | L1: 2031 | M1: 2032 | N1: 2033 | O1: 2034 | P1: 2035 | Q1: 2036 | R1: 2037 | S1: 2038 | T1: 2039 | U1: 2040 | V1: 2041 | W1: 2042 | X1: 2043 | Y1: 2044 | Z1: 2045 | AA1: 2046 | AB1: 2047 | AC1: 2048 | AD1: 2049 | AE1: 2050
A2: battery electric vehicle | B2: 0 | C2: 0 | D2: 0 | E2: 0 | F2: 0 | G2: 0 | H2: 0 | I2: 0 | J2: 0 | K2: 0 | L2: 0 | M2: 0 | N2: 0 | O2: 0 | P2: 0 | Q2: 0 | R2: 0 | S2: 0 | T2: 0 | U2: 0 | V2: 0 | W2: 0 | X2: 0 | Y2: 0 | Z2: 0 | AA2: 0 | AB2: 0 | AC2: 0 | AD2: 0 | AE2: 0
A3: natural gas vehicle | B3: 0 | C3: 0 | D3: 0 | E3: 0 | F3: 0 | G3: 0 | H3: 0 | I3: 0 | J3: 0 | K3: 0 | L3: 0 | M3: 0 | N3: 0 | O3: 0 | P3: 0 | Q3: 0 | R3: 0 | S3: 0 | T3: 0 | U3: 0 | V3: 0 | W3: 0 | X3: 0 | Y3: 0 | Z3: 0 | AA3: 0 | AB3: 0 | AC3: 0 | AD3: 0 | AE3: 0
A4: gasoline vehicle | B4: 0 | C4: 0 | D4: 0 | E4: 0 | F4: 0 | G4: 0 | H4: 0 | I4: 0 | J4: 0 | K4: 0 | L4: 0 | M4: 0 | N4: 0 | O4: 0 | P4: 0 | Q4: 0 | R4: 0 | S4: 0 | T4: 0 | U4: 0 | V4: 0 | W4: 0 | X4: 0 | Y4: 0 | Z4: 0 | AA4: 0 | AB4: 0 | AC4: 0 | AD4: 0 | AE4: 0
A5: diesel vehicle | B5: 0 | C5: 0 | D5: 0 | E5: 0 | F5: 0 | G5: 0 | H5: 0 | I5: 0 | J5: 0 | K5: 0 | L5: 0 | M5: 0 | N5: 0 | O5: 0 | P5: 0 | Q5: 0 | R5: 0 | S5: 0 | T5: 0 | U5: 0 | V5: 0 | W5: 0 | X5: 0 | Y5: 0 | Z5: 0 | AA5: 0 | AB5: 0 | AC5: 0 | AD5: 0 | AE5: 0
A6: plugin hybrid vehicle | B6: 0 | C6: 0 | D6: 0 | E6: 0 | F6: 0 | G6: 0 | H6: 0 | I6: 0 | J6: 0 | K6: 0 | L6: 0 | M6: 0 | N6: 0 | O6: 0 | P6: 0 | Q6: 0 | R6: 0 | S6: 0 | T6: 0 | U6: 0 | V6: 0 | W6: 0 | X6: 0 | Y6: 0 | Z6: 0 | AA6: 0 | AB6: 0 | AC6: 0 | AD6: 0 | AE6: 0
A7: LPG vehicle | B7: 0 | C7: 0 | D7: 0 | E7: 0 | F7: 0 | G7: 0 | H7: 0 | I7: 0 | J7: 0 | K7: 0 | L7: 0 | M7: 0 | N7: 0 | O7: 0 | P7: 0 | Q7: 0 | R7: 0 | S7: 0 | T7: 0 | U7: 0 | V7: 0 | W7: 0 | X7: 0 | Y7: 0 | Z7: 0 | AA7: 0 | AB7: 0 | AC7: 0 | AD7: 0 | AE7: 0
A8: hydrogen vehicle | B8: 0 | C8: 0 | D8: 0 | E8: 0 | F8: 0 | G8: 0 | H8: 0 | I8: 0 | J8: 0 | K8: 0 | L8: 0 | M8: 0 | N8: 0 | O8: 0 | P8: 0 | Q8: 0 | R8: 0 | S8: 0 | T8: 0 | U8: 0 | V8: 0 | W8: 0 | X8: 0 | Y8: 0 | Z8: 0 | AA8: 0 | AB8: 0 | AC8: 0 | AD8: 0 | AE8: 0

Sheet BVS-frgt-motorbikes
A1: Subsidy (2012 USD) | B1: 2021 | C1: 2022 | D1: 2023 | E1: 2024 | F1: 2025 | G1: 2026 | H1: 2027 | I1: 2028 | J1: 2029 | K1: 2030 | L1: 2031 | M1: 2032 | N1: 2033 | O1: 2034 | P1: 2035 | Q1: 2036 | R1: 2037 | S1: 2038 | T1: 2039 | U1: 2040 | V1: 2041 | W1: 2042 | X1: 2043 | Y1: 2044 | Z1: 2045 | AA1: 2046 | AB1: 2047 | AC1: 2048 | AD1: 2049 | AE1: 2050
A2: battery electric vehicle | B2: 0 | C2: 0 | D2: 0 | E2: 0 | F2: 0 | G2: 0 | H2: 0 | I2: 0 | J2: 0 | K2: 0 | L2: 0 | M2: 0 | N2: 0 | O2: 0 | P2: 0 | Q2: 0 | R2: 0 | S2: 0 | T2: 0 | U2: 0 | V2: 0 | W2: 0 | X2: 0 | Y2: 0 | Z2: 0 | AA2: 0 | AB2: 0 | AC2: 0 | AD2: 0 | AE2: 0
A3: natural gas vehicle | B3: 0 | C3: 0 | D3: 0 | E3: 0 | F3: 0 | G3: 0 | H3: 0 | I3: 0 | J3: 0 | K3: 0 | L3: 0 | M3: 0 | N3: 0 | O3: 0 | P3: 0 | Q3: 0 | R3: 0 | S3: 0 | T3: 0 | U3: 0 | V3: 0 | W3: 0 | X3: 0 | Y3: 0 | Z3: 0 | AA3: 0 | AB3: 0 | AC3: 0 | AD3: 0 | AE3: 0
A4: gasoline vehicle | B4: 0 | C4: 0 | D4: 0 | E4: 0 | F4: 0 | G4: 0 | H4: 0 | I4: 0 | J4: 0 | K4: 0 | L4: 0 | M4: 0 | N4: 0 | O4: 0 | P4: 0 | Q4: 0 | R4: 0 | S4: 0 | T4: 0 | U4: 0 | V4: 0 | W4: 0 | X4: 0 | Y4: 0 | Z4: 0 | AA4: 0 | AB4: 0 | AC4: 0 | AD4: 0 | AE4: 0
A5: diesel vehicle | B5: 0 | C5: 0 | D5: 0 | E5: 0 | F5: 0 | G5: 0 | H5: 0 | I5: 0 | J5: 0 | K5: 0 | L5: 0 | M5: 0 | N5: 0 | O5: 0 | P5: 0 | Q5: 0 | R5: 0 | S5: 0 | T5: 0 | U5: 0 | V5: 0 | W5: 0 | X5: 0 | Y5: 0 | Z5: 0 | AA5: 0 | AB5: 0 | AC5: 0 | AD5: 0 | AE5: 0
A6: plugin hybrid vehicle | B6: 0 | C6: 0 | D6: 0 | E6: 0 | F6: 0 | G6: 0 | H6: 0 | I6: 0 | J6: 0 | K6: 0 | L6: 0 | M6: 0 | N6: 0 | O6: 0 | P6: 0 | Q6: 0 | R6: 0 | S6: 0 | T6: 0 | U6: 0 | V6: 0 | W6: 0 | X6: 0 | Y6: 0 | Z6: 0 | AA6: 0 | AB6: 0 | AC6: 0 | AD6: 0 | AE6: 0
A7: LPG vehicle | B7: 0 | C7: 0 | D7: 0 | E7: 0 | F7: 0 | G7: 0 | H7: 0 | I7: 0 | J7: 0 | K7: 0 | L7: 0 | M7: 0 | N7: 0 | O7: 0 | P7: 0 | Q7: 0 | R7: 0 | S7: 0 | T7: 0 | U7: 0 | V7: 0 | W7: 0 | X7: 0 | Y7: 0 | Z7: 0 | AA7: 0 | AB7: 0 | AC7: 0 | AD7: 0 | AE7: 0
A8: hydrogen vehicle | B8: 0 | C8: 0 | D8: 0 | E8: 0 | F8: 0 | G8: 0 | H8: 0 | I8: 0 | J8: 0 | K8: 0 | L8: 0 | M8: 0 | N8: 0 | O8: 0 | P8: 0 | Q8: 0 | R8: 0 | S8: 0 | T8: 0 | U8: 0 | V8: 0 | W8: 0 | X8: 0 | Y8: 0 | Z8: 0 | AA8: 0 | AB8: 0 | AC8: 0 | AD8: 0 | AE8: 0
